<?xml version = "1.0"?>
<sdf version='1.4'>
	
	
	<model name="Astro">

		<static>false</static>

		<link name="base_link">

		<!--Bottom bed of cart-->

			<pose> 0 0 .505 0 0 0 </pose> 
			<inertial>
				<pose>0 0 -.3 0 0 0 </pose>
				<mass> 20 </mass>
			</inertial>
			

			<collision name="bottom_plate">
				<pose> 0 0 -.35 0 0 0 </pose>
				<geometry>
					<box>
          	<size>.762 .4572 .03</size>
					</box>
        </geometry>
			</collision>

			<visual name="bottom_plate">
				<pose> 0 0 -.35 0 0 0 </pose>
				<geometry>
					<box>
          	<size>.762 .4572 .03</size>
					</box>
        </geometry>
			</visual>


				<collision name="lidar_pole">
				<pose> .381 0 .381 0 0 0 </pose>
				<geometry>
					<box>
						<size>.03 .03 .3</size>
					</box>
				</geometry>
			</collision>

			<visual name="lidar_pole">
				<pose> .381 0 .381 0 0 0 </pose>
				<geometry>
					<box>
          	<size>.03 .03 .3</size>
					</box>
        </geometry>
			</visual>
			

			<collision name="top_plate">
				<pose> 0 0 .381 0 0 0 </pose>
				<geometry>
					<box>
						<size>.762 .4572 .03</size>
					</box>
				</geometry>
			</collision>

			<visual name="top_plate">
				<pose> 0 0 .381 0 0 0 </pose>
				<geometry>
					<box>
          	<size>.762 .4572 .03</size>
					</box>
        </geometry>
			</visual>




			<collision name="caster_collision_1">
				<pose> -.3 -.2-.442 0 0 0</pose>	
				<geometry>
					<sphere>	
						<radius>0.06191</radius>
					</sphere>
				</geometry>	
				<surface>
              		<friction>
                		<ode>
                  			<mu>0</mu>
                  			<mu2>0</mu2>
                  			<slip1>1.0</slip1>
                  			<slip2>1.0</slip2>
                		</ode>
              		</friction>
            	</surface>			
			</collision>

			<visual name="caster_visual_1">
				<pose>-.3 -.2 -.442 0 0 0</pose> 
				<geometry>              
                    <sphere>
                        <radius>0.06191</radius>
                	</sphere>
				</geometry>
			</visual>



			<collision name="caster_collision_2">
                <pose>.3 .2 -.442 0 0 0 </pose>
								<geometry>              
                    <sphere>
                        <radius>0.06191</radius>
                		</sphere>
								</geometry>
								<surface>
                    <friction>
                        <ode>
                            <mu>0</mu>
                            <mu2>0</mu2>
                            <slip1>1.0</slip1>
                            <slip2>1.0</slip2>
                        </ode>
                    </friction>
                </surface>
            </collision>
			
			<visual name="caster_visual_2">
                <pose>.3 .2 -.442 0 0 0</pose>
				<geometry>
                    <sphere>
                        <radius>0.06191</radius>
                	</sphere>
				</geometry>
            </visual>


<collision name="caster_collision_3">
                <pose>.3 -.2 -.442 0 0 0</pose>
				<geometry>              
                    <sphere>
                        <radius>0.06191</radius>
                	</sphere>
				</geometry>
				<surface>
                    <friction>
                        <ode>
                            <mu>0</mu>
                            <mu2>0</mu2>
                            <slip1>1.0</slip1>
                            <slip2>1.0</slip2>
                        </ode>
                    </friction>
                </surface>
            </collision>
			
			<visual name="caster_visual_3">
                <pose>.3 -.2 -.442 0 0 0</pose>
				<geometry>
                    <sphere>
                        <radius>0.06191</radius>
                	</sphere>
				</geometry>
            </visual>


			<collision name="caster_collision_4">
      	<pose>-.3 .2 -.442 0 0 0</pose>
					<geometry>              
                    <sphere>
                        <radius>0.06191</radius>
                	</sphere>
					</geometry>
					<surface>
                <friction>
                        <ode>
                            <mu>0</mu>
                            <mu2>0</mu2>
                            <slip1>1.0</slip1>
                            <slip2>1.0</slip2>
                        </ode>
                    </friction>
                </surface>
      </collision>
			
			<visual name="caster_visual_4">
                <pose>-.3 .2 -.442 0 0 0</pose>
				<geometry>
                    <sphere>
                        <radius>0.06191</radius>
                	</sphere>
				</geometry>
       </visual>


		<collision name="pole1">
				<pose>0.381 -.2286 0 0 0 0</pose>
				<geometry>
					<box>
						<size>.03 .03 .762</size>
					</box>
				</geometry>
			</collision>

			<visual name="pole1">
				<pose>0.381 -.2286 0 0 0 0 </pose>
				<geometry>
					<box>
          	<size>.03 .03 .762</size>
					</box>
        </geometry>
			</visual>

<collision name="pole2">
				<pose> 0.381 .2286 0 0 0 0 </pose>
				<geometry>
					<box>
						<size>.03 .03 .762</size>
					</box>
				</geometry>
			</collision>

			<visual name="pole2">
				<pose>0.381 .2286  0 0 0 0</pose>
				<geometry>
					<box>
          	<size>.03 .03 .762</size>
					</box>
        </geometry>
			</visual>

<collision name="pole3">
				<pose>-0.381 .2286  0 0 0 0 </pose>
				<geometry>
					<box>
						<size>.03 .03 .762</size>
					</box>
				</geometry>
			</collision>

			<visual name="pole3">
				<pose>-0.381 .2286  0 0 0 0</pose>
				<geometry>
					<box>
          	<size>.03 .03 .762</size>
					</box>
        </geometry>
			</visual>


<collision name="pole4">
				<pose>-0.381 .2286  0 0 0 0 </pose>
				<geometry>
					<box>
						<size>.03 .03 .762</size>
					</box>
				</geometry>
			</collision>

			<visual name="pole4">
				<pose>-0.381 -.2286  0 0 0 0</pose>
				<geometry>
					<box>
          	<size>.03 .03 .762</size>
					</box>
        </geometry>
			</visual>



		</link>

	

		











		<link name="left_wheel">
			
			<pose>0 -.2  .061 0 1.57 1.57 </pose>
			<inertial>
				<mass>0.5</mass>
			</inertial>
			<collision name="collision">
                <geometry>
                    <cylinder>
                        <radius>0.06191</radius>
                        <length>0.03</length>
                    </cylinder>
                </geometry>
            </collision>
            
			<visual name="visual">
                <geometry>
                    <cylinder>
                        <radius>0.06191</radius>
                        <length>0.03</length>
                    </cylinder>
                </geometry>
            </visual>
		</link>


		<link name="right_wheel">

            <pose>0 .2 .061 0 1.57 1.57 </pose>
						<inertial>
							<mass>0.5</mass>
						</inertial>
            <collision name="collision">
                <geometry>
                    <cylinder>
                        <radius>0.06191</radius>
                        <length>0.03</length>
                    </cylinder>
                </geometry>
            </collision>

            <visual name="visual">
                <geometry>
                    <cylinder>
                        <radius>0.06191</radius>
                        <length>0.03</length>
                    </cylinder>
                </geometry>
            </visual>
    </link>	


		<joint type="revolute" name="left_wheel_hinge">
			<pose>0 0 0 0 0 0 </pose>
			<child>left_wheel</child>
			<parent>base_link</parent>
			<axis>
				<xyz> 0 1 0 </xyz>
			</axis>
		</joint>

		<joint type="revolute" name="right_wheel_hinge">
            <pose>0 0 0 0 0 0 </pose>
            <child>right_wheel</child>
            <parent>base_link</parent>
            <axis>
                <xyz> 0 1 0 </xyz>
            </axis>
        </joint>


    <joint name="hokuyo_joint" type="fixed">
      <child>hokuyo_link</child>
      <parent>base_link</parent>
    </joint>


	<link name="hokuyo_link">
		<pose>.381 0 1.036 0 0 0</pose>
		<inertial>
			<mass>0.1</mass>
		</inertial>
    
		<visual name="visual">
		<geometry>
        	  <mesh>
            	<uri>model://hokuyo/meshes/hokuyo.dae</uri>
          	</mesh>
        	</geometry>
     	 </visual>
    
		<sensor name="head_hokuyo_sensor" type="ray">
        <pose>0 0 0 0 0 0</pose>
        <ray>
          <scan>
            <horizontal>
              <samples>200</samples>
              <resolution>1</resolution>
              <min_angle>-3.1</min_angle>
              <max_angle>3.1</max_angle>
            </horizontal>
          </scan>
          <range>
            <min>0.08</min>
            <max>6</max>
            <resolution>0.01</resolution>
          </range>
        </ray>

        <plugin name="laser" filename="libRayPlugin.so" />
    		<always_on>1</always_on>
        	<update_rate>30</update_rate>
				<visualize>true</visualize>	
		
				<plugin name="gazebo_ros_head_hokuyo_controller" filename="libgazebo_ros_laser.so">
					<topicName>scan</topicName>
					<frameName>Astro/hokuyo_link</frameName>  	
				</plugin>
		</sensor>	

	 </link>



	<plugin name="differential_drive_controller" filename="libgazebo_ros_diff_drive.so">
		

		<legacyMode>true</legacyMode>
			
		<alwaysOn>true</alwaysOn>
		
		<updateRate>30</updateRate>

		<leftJoint>left_wheel_hinge</leftJoint>

		<rightJoint>right_wheel_hinge</rightJoint>

		<wheelSeparation>.4</wheelSeparation>
		
		<wheelDiameter>.12382</wheelDiameter>
		
		<wheelTorque>15</wheelTorque>
			
		<commandTopic>/cmd_vel</commandTopic>
		
		<odometryTopic>odom</odometryTopic>
	
		<odometryFrame>odom</odometryFrame>
		
		<robotBaseFrame>base_link</robotBaseFrame>
		
	</plugin>	


</model>
</sdf>
